test_01 (__main__.TestDemo) ... ok
test_02 (__main__.TestDemo) ... FAIL
test_03 (__main__.TestDemo) ... FAIL

======================================================================
FAIL: test_02 (__main__.TestDemo)
----------------------------------------------------------------------
Traceback (most recent call last):
  File "demo.py", line 16, in test_02
    self.assertEqual(1+1,3,"判断1+1是不是等于3")
AssertionError: 2 != 3 : 判断1+1是不是等于3

======================================================================
FAIL: test_03 (__main__.TestDemo)
----------------------------------------------------------------------
Traceback (most recent call last):
  File "demo.py", line 19, in test_03
    self.assertEqual(1+1,4,"判断1+1是不是等于4")
AssertionError: 2 != 4 : 判断1+1是不是等于4

----------------------------------------------------------------------
Ran 3 tests in 0.004s

FAILED (failures=2)
